Workbook

Sheet Cover
B7: Patient Insights Support - Ticket Overview
B8: Tickets opened with the Pfizer Support team. The purpose of this document is to present an aggregate view of tickets.
B10: Assignment Group: | D10: GBL-C4 MARM PATIENT INSIGHTS SUPPORT & GBL-C4 MARM PATIENT INIGHTS SUPPORT L3
B11: Document Owners: | D11: Robert Peng
B12: Last updated: | D12: Jan/31/2025

Sheet SLA Config
B2: Priority | C2: Resolve SLA
B3: 1 - Critical | C3: 3
B4: 2 - High | C4: 5
B5: 3 - Medium | C5: 15
B6: 4 - Low | C6: 25

Sheet Incidents
A1: Ticket ID | B1: Opened On | C1: Closed On | D1: Status | E1: Assignee | F1: Age (days) | G1: Application Affected | H1: Brief Description | I1: Category | J1: Subcategory | K1: Reporter | L1: Reported By | M1: Priority | N1: SLA Threshold | O1: SLAs Met?
A2: IM44979703 | B2: 45588 | C2: 45598 | D2: Closed | E2: ANANDA40 | F2: =IF(ISBLANK(C2), NETWORKDAYS(B2,TODAY()), NETWORKDAYS(B2,C2)) -> 8 | G2: PASSPORT | H2: Patient Insights | Job (BHVN HUB) not working in DEV | I2: Batch | J2: IICS | K2: GUNDANNA, PUNYA | L2: Support | M2: =VLOOKUP(Incidents[[#This Row],[Ticket ID]],[1]Incidents!$A$2:$D$792,4,FALSE) -> 4 - Low | N2: =VLOOKUP(Incidents[[#This Row],[Priority]],'SLA Config'!$B$3:$C$6,2,FALSE) -> 25 | O2: =IF(Incidents[[#This Row],[Age (days)]]>Incidents[[#This Row],[SLA Threshold]],"NO","Yes") -> Yes
A3: IM44987477 | B3: 45590 | C3: 45598 | D3: Closed | E3: MALLIA04 | F3: =IF(ISBLANK(C3), NETWORKDAYS(B3,TODAY()), NETWORKDAYS(B3,C3)) -> 6 | G3: PASSPORT | H3: TABLEAU | UAT | FW: PIN_SFLK_PATIENT_SUMMARY_AGG_VW Extract Refresh Failed | I3: Batch | J3: Tableau | K3: MALLIKARJUN INGALALLI, ANUPAMA | L3: Support | M3: =VLOOKUP(Incidents[[#This Row],[Ticket ID]],[1]Incidents!$A$2:$D$792,4,FALSE) -> 4 - Low | N3: =VLOOKUP(Incidents[[#This Row],[Priority]],'SLA Config'!$B$3:$C$6,2,FALSE) -> 25 | O3: =IF(Incidents[[#This Row],[Age (days)]]>Incidents[[#This Row],[SLA Threshold]],"NO","Yes") -> Yes
A4: IM44906264 | B4: 45566 | C4: 45572 | D4: Closed | E4: MALLIA04 | F4: =IF(ISBLANK(C4), NETWORKDAYS(B4,TODAY()), NETWORKDAYS(B4,C4)) -> 5 | G4: PASSPORT | H4: Patient Insights | Master Load failed on 9/29 | I4: Batch | J4: IICS | K4: DINALIS, KONSTANTINOS | L4: Support | M4: =VLOOKUP(Incidents[[#This Row],[Ticket ID]],[1]Incidents!$A$2:$D$792,4,FALSE) -> 2 - High | N4: =VLOOKUP(Incidents[[#This Row],[Priority]],'SLA Config'!$B$3:$C$6,2,FALSE) -> 5 | O4: =IF(Incidents[[#This Row],[Age (days)]]>Incidents[[#This Row],[SLA Threshold]],"NO","Yes") -> Yes
A5: IM44922833 | B5: 45572 | C5: 45577 | D5: Closed | E5: GUNDAP04 | F5: =IF(ISBLANK(C5), NETWORKDAYS(B5,TODAY()), NETWORKDAYS(B5,C5)) -> 5 | G5: PASSPORT | H5: Patient Insights | TF_FAL_PAC_LOAD failed 10/4 | I5: Batch | J5: IICS | K5: DINALIS, KONSTANTINOS | L5: Support | M5: =VLOOKUP(Incidents[[#This Row],[Ticket ID]],[1]Incidents!$A$2:$D$792,4,FALSE) -> 2 - High | N5: =VLOOKUP(Incidents[[#This Row],[Priority]],'SLA Config'!$B$3:$C$6,2,FALSE) -> 5 | O5: =IF(Incidents[[#This Row],[Age (days)]]>Incidents[[#This Row],[SLA Threshold]],"NO","Yes") -> Yes
A6: IM44906241 | B6: 45566 | C6: 45571 | D6: Closed | E6: MALLIA04 | F6: =IF(ISBLANK(C6), NETWORKDAYS(B6,TODAY()), NETWORKDAYS(B6,C6)) -> 4 | G6: PASSPORT | H6: Patient Insights | Taskflow Prescriber Writer load failed on 9/23 | I6: Batch | J6: IICS | K6: DINALIS, KONSTANTINOS | L6: Support | M6: =VLOOKUP(Incidents[[#This Row],[Ticket ID]],[1]Incidents!$A$2:$D$792,4,FALSE) -> 3 - Medium | N6: =VLOOKUP(Incidents[[#This Row],[Priority]],'SLA Config'!$B$3:$C$6,2,FALSE) -> 15 | O6: =IF(Incidents[[#This Row],[Age (days)]]>Incidents[[#This Row],[SLA Threshold]],"NO","Yes") -> Yes
A7: IM44906286 | B7: 45566 | C7: 45571 | D7: Closed | E7: GUNDAP04 | F7: =IF(ISBLANK(C7), NETWORKDAYS(B7,TODAY()), NETWORKDAYS(B7,C7)) -> 4 | G7: CHAMP | H7: Patient Insights | CHAMP Taskflow failed on 9/30 | I7: Batch | J7: IICS | K7: DINALIS, KONSTANTINOS | L7: Support | M7: =VLOOKUP(Incidents[[#This Row],[Ticket ID]],[1]Incidents!$A$2:$D$792,4,FALSE) -> 2 - High | N7: =VLOOKUP(Incidents[[#This Row],[Priority]],'SLA Config'!$B$3:$C$6,2,FALSE) -> 5 | O7: =IF(Incidents[[#This Row],[Age (days)]]>Incidents[[#This Row],[SLA Threshold]],"NO","Yes") -> Yes
A8: IM41854611 | B8: 44729 | C8: 44758 | D8: Closed | E8: SIRIVV02 | F8: =IF(ISBLANK(C8), NETWORKDAYS(B8,TODAY()), NETWORKDAYS(B8,C8)) -> 21 | G8: PASSPORT | H8: The Mapping Task mt_pi_trn_trn_performance_summary_volume_update_data_load failed. | I8: Batch | J8: IICS | K8: SIRIVELLA, VISHNU VARDHAN | L8: Support | M8: =VLOOKUP(Incidents[[#This Row],[Ticket ID]],[1]Incidents!$A$2:$D$792,4,FALSE) -> 3 - Medium | N8: =VLOOKUP(Incidents[[#This Row],[Priority]],'SLA Config'!$B$3:$C$6,2,FALSE) -> 15 | O8: =IF(Incidents[[#This Row],[Age (days)]]>Incidents[[#This Row],[SLA Threshold]],"NO","Yes") -> NO
A9: IM44625661 | B9: 45482 | C9: 45507 | D9: Closed | E9: ANANDA40 | F9: =IF(ISBLANK(C9), NETWORKDAYS(B9,TODAY()), NETWORKDAYS(B9,C9)) -> 19 | G9: PASSPORT | H9: Patient Insights | Automatic Tableau data source refresh failure through IICS | I9: Batch | J9: Tableau | K9: DINALIS, KONSTANTINOS | L9: Support | M9: =VLOOKUP(Incidents[[#This Row],[Ticket ID]],[1]Incidents!$A$2:$D$792,4,FALSE) -> 3 - Medium | N9: =VLOOKUP(Incidents[[#This Row],[Priority]],'SLA Config'!$B$3:$C$6,2,FALSE) -> 15 | O9: =IF(Incidents[[#This Row],[Age (days)]]>Incidents[[#This Row],[SLA Threshold]],"NO","Yes") -> NO
A10: IM41861471 | B10: 44732 | C10: 44754 | D10: Closed | E10: MALLIA04 | F10: =IF(ISBLANK(C10), NETWORKDAYS(B10,TODAY()), NETWORKDAYS(B10,C10)) -> 17 | G10: CHAMP | H10: Rider script issue in Dev server for Patient Insight Application | I10: Batch | J10: Rider Script | K10: MALLIKARJUN INGALALLI, ANUPAMA | L10: Support | M10: =VLOOKUP(Incidents[[#This Row],[Ticket ID]],[1]Incidents!$A$2:$D$792,4,FALSE) -> 4 - Low | N10: =VLOOKUP(Incidents[[#This Row],[Priority]],'SLA Config'!$B$3:$C$6,2,FALSE) -> 25 | O10: =IF(Incidents[[#This Row],[Age (days)]]>Incidents[[#This Row],[SLA Threshold]],"NO","Yes") -> Yes
A11: IM42533854 | B11: 44893 | C11: 44913 | D11: Closed | E11: SIRIVV02 | F11: =IF(ISBLANK(C11), NETWORKDAYS(B11,TODAY()), NETWORKDAYS(B11,C11)) -> 15 | G11: PASSPORT | H11: Mapping task mt_pi_stg_trn_ptnt_dim_data_load in passport workflow getting hanged due to memory sort issues | I11: Batch | J11: Job Failure | K11: DINALIS, KONSTANTINOS | L11: Support | M11: =VLOOKUP(Incidents[[#This Row],[Ticket ID]],[1]Incidents!$A$2:$D$792,4,FALSE) -> 4 - Low | N11: =VLOOKUP(Incidents[[#This Row],[Priority]],'SLA Config'!$B$3:$C$6,2,FALSE) -> 25 | O11: =IF(Incidents[[#This Row],[Age (days)]]>Incidents[[#This Row],[SLA Threshold]],"NO","Yes") -> Yes
A12: IM43777508 | B12: 45232 | C12: 45249 | D12: Closed | E12: MALLIA04 | F12: =IF(ISBLANK(C12), NETWORKDAYS(B12,TODAY()), NETWORKDAYS(B12,C12)) -> 12 | G12: PASSPORT | H12: Patient Insight Application | TF_MASTER_HUB_PJT_LOAD getting failed from 28/11 | I12: Batch | J12: Job Failure | K12: MALLIKARJUN INGALALLI, ANUPAMA | L12: Support | M12: =VLOOKUP(Incidents[[#This Row],[Ticket ID]],[1]Incidents!$A$2:$D$792,4,FALSE) -> 2 - High | N12: =VLOOKUP(Incidents[[#This Row],[Priority]],'SLA Config'!$B$3:$C$6,2,FALSE) -> 5 | O12: =IF(Incidents[[#This Row],[Age (days)]]>Incidents[[#This Row],[SLA Threshold]],"NO","Yes") -> NO
A13: IM44497164 | B13: 45442 | C13: 45459 | D13: Closed | E13: ANANDA40 | F13: =IF(ISBLANK(C13), NETWORKDAYS(B13,TODAY()), NETWORKDAYS(B13,C13)) -> 12 | G13: PASSPORT | H13: Trigger the TALZENNA Taskflow in UAT environment. | I13: Batch | J13: Ad-hoc job | K13: VEMURI, VISHAL | L13: Digital | M13: =VLOOKUP(Incidents[[#This Row],[Ticket ID]],[1]Incidents!$A$2:$D$792,4,FALSE) -> 4 - Low | N13: =VLOOKUP(Incidents[[#This Row],[Priority]],'SLA Config'!$B$3:$C$6,2,FALSE) -> 25 | O13: =IF(Incidents[[#This Row],[Age (days)]]>Incidents[[#This Row],[SLA Threshold]],"NO","Yes") -> Yes
... A110: IM44368751 | B110: 45405 | C110: 45465 | D110: Closed | E110: ANANDA40 | F110: =IF(ISBLANK(C110), NETWORKDAYS(B110,TODAY()), NETWORKDAYS(B110,C110)) -> 44 | G110: PASSPORT | H110: Patient Insight |Data mismatch for the ACCOUNT, ACCOUNT_TYPE columns in Ibrance, Xeljanz - Persistency Mappings | I110: Data Issue | J110: Snowflake | K110: CHENNAM, VAMSIKRISHNA | L110: Digital | M110: =VLOOKUP(Incidents[[#This Row],[Ticket ID]],[1]Incidents!$A$2:$D$792,4,FALSE) -> 3 - Medium | N110: =VLOOKUP(Incidents[[#This Row],[Priority]],'SLA Config'!$B$3:$C$6,2,FALSE) -> 15 | O110: =IF(Incidents[[#This Row],[Age (days)]]>Incidents[[#This Row],[SLA Threshold]],"NO","Yes") -> NO
A111: IM45111282 | B111: 45629 | C111: 45690 | D111: Closed | E111: ANANDA40 | F111: =IF(ISBLANK(C111), NETWORKDAYS(B111,TODAY()), NETWORKDAYS(B111,C111)) -> 44 | G111: PASSPORT | H111: AMBA data differences between Walgreens and patient insight extraction | I111: Data Issue | K111: GOLDSMITH, GEORGE | M111: =VLOOKUP(Incidents[[#This Row],[Ticket ID]],[1]Incidents!$A$2:$D$792,4,FALSE) -> 3 - Medium | N111: =VLOOKUP(Incidents[[#This Row],[Priority]],'SLA Config'!$B$3:$C$6,2,FALSE) -> 15 | O111: =IF(Incidents[[#This Row],[Age (days)]]>Incidents[[#This Row],[SLA Threshold]],"NO","Yes") -> NO
A112: IM43067170 | B112: 45035 | C112: 45095 | D112: Closed | E112: GANJR04 | F112: =IF(ISBLANK(C112), NETWORKDAYS(B112,TODAY()), NETWORKDAYS(B112,C112)) -> 43 | G112: PASSPORT | H112: Patient Insights - Fulfillment rate and network calculation logic | I112: Data Issue | J112: Tableau | K112: DESAI, RAJ | L112: Business | M112: =VLOOKUP(Incidents[[#This Row],[Ticket ID]],[1]Incidents!$A$2:$D$792,4,FALSE) -> 4 - Low | N112: =VLOOKUP(Incidents[[#This Row],[Priority]],'SLA Config'!$B$3:$C$6,2,FALSE) -> 25 | O112: =IF(Incidents[[#This Row],[Age (days)]]>Incidents[[#This Row],[SLA Threshold]],"NO","Yes") -> NO
A113: IM45135442 | B113: 45637 | C113: 45740 | D113: Closed | E113: MALLIA04 | F113: =IF(ISBLANK(C113), NETWORKDAYS(B113,TODAY()), NETWORKDAYS(B113,C113)) -> 74 | G113: CHAMP | H113: Patient Insights - Data Issue | I113: Data Issue | K113: TROUGHT, ALLISON | L113: Business | M113: =VLOOKUP(Incidents[[#This Row],[Ticket ID]],[1]Incidents!$A$2:$D$792,4,FALSE) -> 3 - Medium | N113: =VLOOKUP(Incidents[[#This Row],[Priority]],'SLA Config'!$B$3:$C$6,2,FALSE) -> 15 | O113: =IF(Incidents[[#This Row],[Age (days)]]>Incidents[[#This Row],[SLA Threshold]],"NO","Yes") -> NO
A114: IM44591811 | B114: 45471 | C114: 45528 | D114: Closed | E114: DINALK01 | F114: =IF(ISBLANK(C114), NETWORKDAYS(B114,TODAY()), NETWORKDAYS(B114,C114)) -> 41 | G114: PASSPORT | H114: Amba Dashboard Data Inquiry | I114: Data Issue | J114: Tableau | K114: ALTER, JONATHAN MICHAEL | L114: Business | M114: =VLOOKUP(Incidents[[#This Row],[Ticket ID]],[1]Incidents!$A$2:$D$792,4,FALSE) -> 4 - Low | N114: =VLOOKUP(Incidents[[#This Row],[Priority]],'SLA Config'!$B$3:$C$6,2,FALSE) -> 25 | O114: =IF(Incidents[[#This Row],[Age (days)]]>Incidents[[#This Row],[SLA Threshold]],"NO","Yes") -> NO
A115: IM43644345 | B115: 45195 | C115: 45249 | D115: Closed | E115: MALLIA04 | F115: =IF(ISBLANK(C115), NETWORKDAYS(B115,TODAY()), NETWORKDAYS(B115,C115)) -> 39 | G115: CHAMP | H115: Patient Insights - DON Services data issue | I115: Data Issue | J115: Web App | K115: TROUGHT, ALLISON | L115: Business | M115: =VLOOKUP(Incidents[[#This Row],[Ticket ID]],[1]Incidents!$A$2:$D$792,4,FALSE) -> 4 - Low | N115: =VLOOKUP(Incidents[[#This Row],[Priority]],'SLA Config'!$B$3:$C$6,2,FALSE) -> 25 | O115: =IF(Incidents[[#This Row],[Age (days)]]>Incidents[[#This Row],[SLA Threshold]],"NO","Yes") -> NO
A116: IM43606214 | B116: 45184 | C116: 45237 | D116: Closed | E116: DINALK01 | F116: =IF(ISBLANK(C116), NETWORKDAYS(B116,TODAY()), NETWORKDAYS(B116,C116)) -> 38 | G116: PASSPORT | H116: Patient Insights | SONEXUS | Triage Data questions | I116: Data Issue | J116: Question | K116: SAMIAYYAN, SHANMUGAM | L116: Digital | M116: =VLOOKUP(Incidents[[#This Row],[Ticket ID]],[1]Incidents!$A$2:$D$792,4,FALSE) -> 4 - Low | N116: =VLOOKUP(Incidents[[#This Row],[Priority]],'SLA Config'!$B$3:$C$6,2,FALSE) -> 25 | O116: =IF(Incidents[[#This Row],[Age (days)]]>Incidents[[#This Row],[SLA Threshold]],"NO","Yes") -> NO
A117: IM44561005 | B117: 45462 | C117: 45514 | D117: Closed | E117: DINALK01 | F117: =IF(ISBLANK(C117), NETWORKDAYS(B117,TODAY()), NETWORKDAYS(B117,C117)) -> 38 | G117: PASSPORT | H117: Patient Insights | DERM | HCO Phone and Fax length issue | I117: Data Issue | J117: Sonexus | K117: SHAIK, SADHATHAMEED | L117: Digital | M117: =VLOOKUP(Incidents[[#This Row],[Ticket ID]],[1]Incidents!$A$2:$D$792,4,FALSE) -> 4 - Low | N117: =VLOOKUP(Incidents[[#This Row],[Priority]],'SLA Config'!$B$3:$C$6,2,FALSE) -> 25 | O117: =IF(Incidents[[#This Row],[Age (days)]]>Incidents[[#This Row],[SLA Threshold]],"NO","Yes") -> NO
A118: IM45135126 | B118: 45637 | C118: 45690 | D118: Closed | E118: ANANDA40 | F118: =IF(ISBLANK(C118), NETWORKDAYS(B118,TODAY()), NETWORKDAYS(B118,C118)) -> 38 | G118: PASSPORT | H118: Patient Insights -FRM Dashboard: Vyndamax data not populating | I118: Data Issue | J118: Tableau | K118: WANG, ERIC | L118: Business | M118: =VLOOKUP(Incidents[[#This Row],[Ticket ID]],[1]Incidents!$A$2:$D$792,4,FALSE) -> 2 - High | N118: =VLOOKUP(Incidents[[#This Row],[Priority]],'SLA Config'!$B$3:$C$6,2,FALSE) -> 5 | O118: =IF(Incidents[[#This Row],[Age (days)]]>Incidents[[#This Row],[SLA Threshold]],"NO","Yes") -> NO
A119: IM44084842 | B119: 45321 | C119: 45371 | D119: Closed | E119: ANANDA40 | F119: =IF(ISBLANK(C119), NETWORKDAYS(B119,TODAY()), NETWORKDAYS(B119,C119)) -> 37 | G119: PASSPORT | H119: Patient Insights | Texas Account Mapping | I119: Data Issue | J119: Tableau | K119: ANAND, ASHISH | L119: Support | M119: =VLOOKUP(Incidents[[#This Row],[Ticket ID]],[1]Incidents!$A$2:$D$792,4,FALSE) -> 4 - Low | N119: =VLOOKUP(Incidents[[#This Row],[Priority]],'SLA Config'!$B$3:$C$6,2,FALSE) -> 25 | O119: =IF(Incidents[[#This Row],[Age (days)]]>Incidents[[#This Row],[SLA Threshold]],"NO","Yes") -> NO
A120: IM44260802 | B120: 45372 | C120: 45423 | D120: Closed | E120: MALLIA04 | F120: =IF(ISBLANK(C120), NETWORKDAYS(B120,TODAY()), NETWORKDAYS(B120,C120)) -> 37 | G120: CHAMP | H120: Patient Insights - CHAMP :missing SPIF for Walgreens Vyndaqel/Vyndamax | I120: Data Issue | J120: Tableau | K120: TROUGHT, ALLISON | L120: Business | M120: =VLOOKUP(Incidents[[#This Row],[Ticket ID]],[1]Incidents!$A$2:$D$792,4,FALSE) -> 2 - High | N120: =VLOOKUP(Incidents[[#This Row],[Priority]],'SLA Config'!$B$3:$C$6,2,FALSE) -> 5 | O120: =IF(Incidents[[#This Row],[Age (days)]]>Incidents[[#This Row],[SLA Threshold]],"NO","Yes") -> NO
A121: IM44838337 | B121: 45545 | C121: 45595 | D121: Closed | E121: MALLIA04 | F121: =IF(ISBLANK(C121), NETWORKDAYS(B121,TODAY()), NETWORKDAYS(B121,C121)) -> 37 | G121: PASSPORT | H121: Patient Insights | Primary_payer_pcn values are populating as null - Patient Summary Load mappings | I121: Data Issue | J121: Tableau | K121: MALLIKARJUN INGALALLI, ANUPAMA | L121: Support | M121: =VLOOKUP(Incidents[[#This Row],[Ticket ID]],[1]Incidents!$A$2:$D$792,4,FALSE) -> 3 - Medium | N121: =VLOOKUP(Incidents[[#This Row],[Priority]],'SLA Config'!$B$3:$C$6,2,FALSE) -> 15 | O121: =IF(Incidents[[#This Row],[Age (days)]]>Incidents[[#This Row],[SLA Threshold]],"NO","Yes") -> NO
A122: IM43606115 | B122: 45184 | C122: 45235 | D122: Closed | E122: DINALK01 | F122: =IF(ISBLANK(C122), NETWORKDAYS(B122,TODAY()), NETWORKDAYS(B122,C122)) -> 36 | G122: PASSPORT | H122: Patient Insights | LASH | Triage Data questions | I122: Data Issue | J122: Question | K122: SAMIAYYAN, SHANMUGAM | L122: Digital | M122: =VLOOKUP(Incidents[[#This Row],[Ticket ID]],[1]Incidents!$A$2:$D$792,4,FALSE) -> 4 - Low | N122: =VLOOKUP(Incidents[[#This Row],[Priority]],'SLA Config'!$B$3:$C$6,2,FALSE) -> 25 | O122: =IF(Incidents[[#This Row],[Age (days)]]>Incidents[[#This Row],[SLA Threshold]],"NO","Yes") -> NO
A123: IM43792481 | B123: 45237 | C123: 45286 | D123: Closed | E123: ANANDA40 | F123: =IF(ISBLANK(C123), NETWORKDAYS(B123,TODAY()), NETWORKDAYS(B123,C123)) -> 36 | G123: CHAMP | H123: Patient Insights - CHAMP SPP Validation - Data Issue | I123: Data Issue | J123: Tableau | K123: TROUGHT, ALLISON | L123: Business | M123: =VLOOKUP(Incidents[[#This Row],[Ticket ID]],[1]Incidents!$A$2:$D$792,4,FALSE) -> 4 - Low | N123: =VLOOKUP(Incidents[[#This Row],[Priority]],'SLA Config'!$B$3:$C$6,2,FALSE) -> 25 | O123: =IF(Incidents[[#This Row],[Age (days)]]>Incidents[[#This Row],[SLA Threshold]],"NO","Yes") -> NO
A124: IM43262030 | B124: 45090 | C124: 45138 | D124: Closed | E124: BABUS32 | F124: =IF(ISBLANK(C124), NETWORKDAYS(B124,TODAY()), NETWORKDAYS(B124,C124)) -> 35 | G124: PASSPORT | H124: Patient Insights - AMBA Dashboard refresh date | I124: Data Issue | J124: Tableau | K124: ALTER, JONATHAN MICHAEL | L124: Business | M124: =VLOOKUP(Incidents[[#This Row],[Ticket ID]],[1]Incidents!$A$2:$D$792,4,FALSE) -> 3 - Medium | N124: =VLOOKUP(Incidents[[#This Row],[Priority]],'SLA Config'!$B$3:$C$6,2,FALSE) -> 15 | O124: =IF(Incidents[[#This Row],[Age (days)]]>Incidents[[#This Row],[SLA Threshold]],"NO","Yes") -> NO
A125: IM43612488 | B125: 45187 | C125: 45235 | D125: Closed | E125: DINALK01 | F125: =IF(ISBLANK(C125), NETWORKDAYS(B125,TODAY()), NETWORKDAYS(B125,C125)) -> 35 | G125: PASSPORT | H125: Patient Insights | LASH | PAC data question | I125: Data Issue | J125: Question | K125: SAMIAYYAN, SHANMUGAM | L125: Digital | M125: =VLOOKUP(Incidents[[#This Row],[Ticket ID]],[1]Incidents!$A$2:$D$792,4,FALSE) -> 4 - Low | N125: =VLOOKUP(Incidents[[#This Row],[Priority]],'SLA Config'!$B$3:$C$6,2,FALSE) -> 25 | O125: =IF(Incidents[[#This Row],[Age (days)]]>Incidents[[#This Row],[SLA Threshold]],"NO","Yes") -> NO
... A179: IM44194762 | B179: 45352 | C179: 45367 | D179: Closed | E179: DINALK01 | F179: =IF(ISBLANK(C179), NETWORKDAYS(B179,TODAY()), NETWORKDAYS(B179,C179)) -> 11 | G179: CHAMP | H179: Patient Insights - champ -Data Issue for Kroger account | I179: Data Issue | J179: Tableau | K179: TROUGHT, ALLISON | L179: Business | M179: =VLOOKUP(Incidents[[#This Row],[Ticket ID]],[1]Incidents!$A$2:$D$792,4,FALSE) -> 4 - Low | N179: =VLOOKUP(Incidents[[#This Row],[Priority]],'SLA Config'!$B$3:$C$6,2,FALSE) -> 25 | O179: =IF(Incidents[[#This Row],[Age (days)]]>Incidents[[#This Row],[SLA Threshold]],"NO","Yes") -> Yes
A180: IM45245485 | B180: 45679 | C180: 45693 | D180: Closed | E180: BABUS32 | F180: =IF(ISBLANK(C180), NETWORKDAYS(B180,TODAY()), NETWORKDAYS(B180,C180)) -> 11 | G180: CHAMP | H180: Patient Insights - Data Issue | I180: Data Issue | K180: TROUGHT, ALLISON | L180: Business | M180: =VLOOKUP(Incidents[[#This Row],[Ticket ID]],[1]Incidents!$A$2:$D$792,4,FALSE) -> 2 - High | N180: =VLOOKUP(Incidents[[#This Row],[Priority]],'SLA Config'!$B$3:$C$6,2,FALSE) -> 5 | O180: =IF(Incidents[[#This Row],[Age (days)]]>Incidents[[#This Row],[SLA Threshold]],"NO","Yes") -> NO
A181: IM45289084 | B181: 45694 | C181: 45703 | D181: Closed | E181: MALLIA04 | F181: =IF(ISBLANK(C181), NETWORKDAYS(B181,TODAY()), NETWORKDAYS(B181,C181)) -> 7 | G181: CHAMP | H181: Patient Insights - Data Issue | I181: Data Issue | K181: TROUGHT, ALLISON | L181: Business | M181: =VLOOKUP(Incidents[[#This Row],[Ticket ID]],[1]Incidents!$A$2:$D$792,4,FALSE) -> 3 - Medium | N181: =VLOOKUP(Incidents[[#This Row],[Priority]],'SLA Config'!$B$3:$C$6,2,FALSE) -> 15 | O181: =IF(Incidents[[#This Row],[Age (days)]]>Incidents[[#This Row],[SLA Threshold]],"NO","Yes") -> Yes
A182: IM45279941 | B182: 45692 | C182: 45699 | D182: Closed | E182: MALLIA04 | F182: =IF(ISBLANK(C182), NETWORKDAYS(B182,TODAY()), NETWORKDAYS(B182,C182)) -> 6 | G182: CHAMP | H182: Plan Payer channel mapping question - FAL | I182: Data Issue | K182: HAQUE, ASAD UL | M182: =VLOOKUP(Incidents[[#This Row],[Ticket ID]],[1]Incidents!$A$2:$D$792,4,FALSE) -> 4 - Low | N182: =VLOOKUP(Incidents[[#This Row],[Priority]],'SLA Config'!$B$3:$C$6,2,FALSE) -> 25 | O182: =IF(Incidents[[#This Row],[Age (days)]]>Incidents[[#This Row],[SLA Threshold]],"NO","Yes") -> Yes
A183: IM42202493 | B183: 44817 | C183: 44830 | D183: Closed | E183: SIRIVV02 | F183: =IF(ISBLANK(C183), NETWORKDAYS(B183,TODAY()), NETWORKDAYS(B183,C183)) -> 10 | G183: PASSPORT | H183: PASSPORT | Metrics for recent quarters are not showing up in the platform. | I183: Data Issue | J183: Tableau | K183: THANGAVEL, RAMESH | L183: Business | M183: =VLOOKUP(Incidents[[#This Row],[Ticket ID]],[1]Incidents!$A$2:$D$792,4,FALSE) -> 3 - Medium | N183: =VLOOKUP(Incidents[[#This Row],[Priority]],'SLA Config'!$B$3:$C$6,2,FALSE) -> 15 | O183: =IF(Incidents[[#This Row],[Age (days)]]>Incidents[[#This Row],[SLA Threshold]],"NO","Yes") -> Yes
A184: IM42202626 | B184: 44817 | C184: 44830 | D184: Closed | E184: SIRIVV02 | F184: =IF(ISBLANK(C184), NETWORKDAYS(B184,TODAY()), NETWORKDAYS(B184,C184)) -> 10 | G184: PASSPORT | H184: Passport | Wrong products getting included in portfolio level reports. | I184: Data Issue | J184: Tableau | K184: THANGAVEL, RAMESH | L184: Business | M184: =VLOOKUP(Incidents[[#This Row],[Ticket ID]],[1]Incidents!$A$2:$D$792,4,FALSE) -> 4 - Low | N184: =VLOOKUP(Incidents[[#This Row],[Priority]],'SLA Config'!$B$3:$C$6,2,FALSE) -> 25 | O184: =IF(Incidents[[#This Row],[Age (days)]]>Incidents[[#This Row],[SLA Threshold]],"NO","Yes") -> Yes
A185: IM42905363 | B185: 44991 | C185: 45003 | D185: Closed | E185: SIRIVV02 | F185: =IF(ISBLANK(C185), NETWORKDAYS(B185,TODAY()), NETWORKDAYS(B185,C185)) -> 10 | G185: CHAMP | H185: Patient Point - Contract 4852 missing start dates | I185: Data Issue | J185: Web App | K185: TROUGHT, ALLISON | L185: Business | M185: =VLOOKUP(Incidents[[#This Row],[Ticket ID]],[1]Incidents!$A$2:$D$792,4,FALSE) -> 4 - Low | N185: =VLOOKUP(Incidents[[#This Row],[Priority]],'SLA Config'!$B$3:$C$6,2,FALSE) -> 25 | O185: =IF(Incidents[[#This Row],[Age (days)]]>Incidents[[#This Row],[SLA Threshold]],"NO","Yes") -> Yes
A186: IM44232550 | B186: 45364 | C186: 45377 | D186: Closed | E186: MALLIA04 | F186: =IF(ISBLANK(C186), NETWORKDAYS(B186,TODAY()), NETWORKDAYS(B186,C186)) -> 10 | G186: CHAMP | H186: IM44232550 - CHAMP is not picking up SPIF for CVS Caremark Vyndaqel program | I186: Data Issue | J186: Tableau | K186: TROUGHT, ALLISON | L186: Business | M186: =VLOOKUP(Incidents[[#This Row],[Ticket ID]],[1]Incidents!$A$2:$D$792,4,FALSE) -> 3 - Medium | N186: =VLOOKUP(Incidents[[#This Row],[Priority]],'SLA Config'!$B$3:$C$6,2,FALSE) -> 15 | O186: =IF(Incidents[[#This Row],[Age (days)]]>Incidents[[#This Row],[SLA Threshold]],"NO","Yes") -> Yes
A187: IM44559176 | B187: 45461 | C187: 45474 | D187: Closed | E187: MALLIA04 | F187: =IF(ISBLANK(C187), NETWORKDAYS(B187,TODAY()), NETWORKDAYS(B187,C187)) -> 10 | G187: CHAMP | H187: Patient Insights - Optum/Somavert Welcome Calls - November 2023 mismatch | I187: Data Issue | J187: Tableau | K187: TROUGHT, ALLISON | L187: Business | M187: =VLOOKUP(Incidents[[#This Row],[Ticket ID]],[1]Incidents!$A$2:$D$792,4,FALSE) -> 4 - Low | N187: =VLOOKUP(Incidents[[#This Row],[Priority]],'SLA Config'!$B$3:$C$6,2,FALSE) -> 25 | O187: =IF(Incidents[[#This Row],[Age (days)]]>Incidents[[#This Row],[SLA Threshold]],"NO","Yes") -> Yes
A188: IM44643718 | B188: 45488 | C188: 45500 | D188: Closed | E188: DINALK01 | F188: =IF(ISBLANK(C188), NETWORKDAYS(B188,TODAY()), NETWORKDAYS(B188,C188)) -> 10 | G188: PASSPORT | H188: SPP Data Issue for XELJANZ,CIBINQO,LITFULO,VELSIPITY | I188: Data Issue | J188: Tableau | K188: PARAMESWARAN, KARTHIGA | L188: Digital | M188: =VLOOKUP(Incidents[[#This Row],[Ticket ID]],[1]Incidents!$A$2:$D$792,4,FALSE) -> 2 - High | N188: =VLOOKUP(Incidents[[#This Row],[Priority]],'SLA Config'!$B$3:$C$6,2,FALSE) -> 5 | O188: =IF(Incidents[[#This Row],[Age (days)]]>Incidents[[#This Row],[SLA Threshold]],"NO","Yes") -> NO
A189: IM44791815 | B189: 45530 | C189: 45542 | D189: Closed | E189: MALLIA04 | F189: =IF(ISBLANK(C189), NETWORKDAYS(B189,TODAY()), NETWORKDAYS(B189,C189)) -> 10 | G189: CHAMP | H189: Patient Insights - Incorrect missing invoice message for Contract 4879 | I189: Data Issue | J189: Tableau | K189: TROUGHT, ALLISON | L189: Business | M189: =VLOOKUP(Incidents[[#This Row],[Ticket ID]],[1]Incidents!$A$2:$D$792,4,FALSE) -> 3 - Medium | N189: =VLOOKUP(Incidents[[#This Row],[Priority]],'SLA Config'!$B$3:$C$6,2,FALSE) -> 15 | O189: =IF(Incidents[[#This Row],[Age (days)]]>Incidents[[#This Row],[SLA Threshold]],"NO","Yes") -> Yes
...

Sheet Requests
A1: Ticket ID | B1: Opened On | C1: Closed On | D1: Status | E1: Assignee | F1: Age (days) | G1: Application Affected | H1: Brief Description | I1: Category | J1: Subcategory | K1: Reporter | L1: Requested By | M1: Priority | N1: SLA Threshold | O1: SLAs Met?
A2: RF3622712 | B2: 44648 | C2: 44662 | D2: Closed | E2: MALLIA04 | F2: =IF(ISBLANK(C2), NETWORKDAYS(B2,TODAY()), NETWORKDAYS(B2,C2)) -> 11 | G2: CHAMP | H2: GMFT reconfiguration required in DEV S3 | I2: Enhancement | J2: Batch | K2: SHAJI, GENUINE | L2: Digital | M2: =VLOOKUP(Requests[[#This Row],[Ticket ID]],[2]Requests!$A$2:$D$649,4,FALSE) -> 4 - Low | N2: =VLOOKUP(Requests[[#This Row],[Priority]],'SLA Config'!$B$3:$C$6,2,FALSE) -> 25 | O2: =IF(Requests[[#This Row],[Age (days)]]>Requests[[#This Row],[SLA Threshold]],"Yes","No") -> No
A3: RF3658439 | B3: 44666 | C3: 44691 | D3: Closed | E3: MALLIA04 | F3: =IF(ISBLANK(C3), NETWORKDAYS(B3,TODAY()), NETWORKDAYS(B3,C3)) -> 18 | G3: PASSPORT | H3: Request: Passport Leave Behind Deck extraction Q1 2022 | I3: Report | J3: Leave Behind Deck | K3: SHAJI, GENUINE | L3: Business | M3: =VLOOKUP(Requests[[#This Row],[Ticket ID]],[2]Requests!$A$2:$D$649,4,FALSE) -> 4 - Low | N3: =VLOOKUP(Requests[[#This Row],[Priority]],'SLA Config'!$B$3:$C$6,2,FALSE) -> 25 | O3: =IF(Requests[[#This Row],[Age (days)]]>Requests[[#This Row],[SLA Threshold]],"Yes","No") -> No
A4: RF3780202 | B4: 44738 | C4: 44745 | D4: Closed | E4: DINALK01 | F4: =IF(ISBLANK(C4), NETWORKDAYS(B4,TODAY()), NETWORKDAYS(B4,C4)) -> 5 | G4: CHAMP | H4: SM Data Quality Discrepancy Report [Change Mgmt General]: GBL-C4 MARM PATIENT INSIGHTS SUPPORT | I4: Audit | J4: Service Manager RFC | K4: DIGITAL CONFIGURATION MGMT, CI DATA QUALITY | L4: Digital | M4: =VLOOKUP(Requests[[#This Row],[Ticket ID]],[2]Requests!$A$2:$D$649,4,FALSE) -> 4 - Low | N4: =VLOOKUP(Requests[[#This Row],[Priority]],'SLA Config'!$B$3:$C$6,2,FALSE) -> 25 | O4: =IF(Requests[[#This Row],[Age (days)]]>Requests[[#This Row],[SLA Threshold]],"Yes","No") -> No
A5: RF3818389 | B5: 44761 | C5: 44807 | D5: Closed | E5: SIRIVV02 | F5: =IF(ISBLANK(C5), NETWORKDAYS(B5,TODAY()), NETWORKDAYS(B5,C5)) -> 34 | G5: PASSPORT | H5: Vyndamax Patient Experience Report | Access permission for specific views | I5: User Access | J5: Information/How-To | K5: DING, MING | L5: Business | M5: =VLOOKUP(Requests[[#This Row],[Ticket ID]],[2]Requests!$A$2:$D$649,4,FALSE) -> 4 - Low | N5: =VLOOKUP(Requests[[#This Row],[Priority]],'SLA Config'!$B$3:$C$6,2,FALSE) -> 25 | O5: =IF(Requests[[#This Row],[Age (days)]]>Requests[[#This Row],[SLA Threshold]],"Yes","No") -> Yes
A6: RF3833207 | B6: 44770 | C6: 44788 | D6: Closed | E6: MALLIA04 | F6: =IF(ISBLANK(C6), NETWORKDAYS(B6,TODAY()), NETWORKDAYS(B6,C6)) -> 13 | G6: PASSPORT | H6: Leave Behind deck extract Q2 2022 | I6: Report | J6: Leave Behind Deck | K6: THANGAVEL, RAMESH | L6: Business | M6: =VLOOKUP(Requests[[#This Row],[Ticket ID]],[2]Requests!$A$2:$D$649,4,FALSE) -> 4 - Low | N6: =VLOOKUP(Requests[[#This Row],[Priority]],'SLA Config'!$B$3:$C$6,2,FALSE) -> 25 | O6: =IF(Requests[[#This Row],[Age (days)]]>Requests[[#This Row],[SLA Threshold]],"Yes","No") -> No
A7: RF3847340 | B7: 44778 | C7: 44789 | D7: Closed | E7: SIRIVV02 | F7: =IF(ISBLANK(C7), NETWORKDAYS(B7,TODAY()), NETWORKDAYS(B7,C7)) -> 8 | G7: PASSPORT | H7: Access to Vyndamax patient experience report | I7: User Access | J7: Add | K7: DING, MING | L7: Business | M7: =VLOOKUP(Requests[[#This Row],[Ticket ID]],[2]Requests!$A$2:$D$649,4,FALSE) -> 4 - Low | N7: =VLOOKUP(Requests[[#This Row],[Priority]],'SLA Config'!$B$3:$C$6,2,FALSE) -> 25 | O7: =IF(Requests[[#This Row],[Age (days)]]>Requests[[#This Row],[SLA Threshold]],"Yes","No") -> No
A8: RF3868923 | B8: 44792 | C8: 44802 | D8: Closed | E8: SIRIVV02 | F8: =IF(ISBLANK(C8), NETWORKDAYS(B8,TODAY()), NETWORKDAYS(B8,C8)) -> 7 | G8: PASSPORT | H8: Request - Need to add create new security AD- Groups for patient insights | I8: User Access | J8: Security Group | K8: DINALIS, KONSTANTINOS | L8: Digital | M8: =VLOOKUP(Requests[[#This Row],[Ticket ID]],[2]Requests!$A$2:$D$649,4,FALSE) -> 3 - Medium | N8: =VLOOKUP(Requests[[#This Row],[Priority]],'SLA Config'!$B$3:$C$6,2,FALSE) -> 15 | O8: =IF(Requests[[#This Row],[Age (days)]]>Requests[[#This Row],[SLA Threshold]],"Yes","No") -> No
A9: RF3879799 | B9: 44798 | C9: 44816 | D9: Closed | E9: SIRIVV02 | F9: =IF(ISBLANK(C9), NETWORKDAYS(B9,TODAY()), NETWORKDAYS(B9,C9)) -> 13 | G9: CHAMP | H9: Patient Point - Add two new services | I9: Enhancement | J9: Data Update | K9: TROUGHT, ALLISON | L9: Business | M9: =VLOOKUP(Requests[[#This Row],[Ticket ID]],[2]Requests!$A$2:$D$649,4,FALSE) -> 4 - Low | N9: =VLOOKUP(Requests[[#This Row],[Priority]],'SLA Config'!$B$3:$C$6,2,FALSE) -> 25 | O9: =IF(Requests[[#This Row],[Age (days)]]>Requests[[#This Row],[SLA Threshold]],"Yes","No") -> No
A10: RF3891413 | B10: 44805 | C10: 44815 | D10: Closed | E10: SIRIVV02 | F10: =IF(ISBLANK(C10), NETWORKDAYS(B10,TODAY()), NETWORKDAYS(B10,C10)) -> 7 | G10: CHAMP | H10: Request to provide access for Patient Point | I10: User Access | J10: Add | K10: TROUGHT, ALLISON | L10: Business | M10: =VLOOKUP(Requests[[#This Row],[Ticket ID]],[2]Requests!$A$2:$D$649,4,FALSE) -> 4 - Low | N10: =VLOOKUP(Requests[[#This Row],[Priority]],'SLA Config'!$B$3:$C$6,2,FALSE) -> 25 | O10: =IF(Requests[[#This Row],[Age (days)]]>Requests[[#This Row],[SLA Threshold]],"Yes","No") -> No
A11: RF3892187 | B11: 44805 | C11: 44816 | D11: Closed | E11: SIRIVV02 | F11: =IF(ISBLANK(C11), NETWORKDAYS(B11,TODAY()), NETWORKDAYS(B11,C11)) -> 8 | G11: CHAMP | H11: RM Fulfillment Ticket: Patient Insights - 20220901020530402 | I11: User Access | J11: Add | K11: NAGARAJU, SUNIL KUMAR | L11: Digital | M11: =VLOOKUP(Requests[[#This Row],[Ticket ID]],[2]Requests!$A$2:$D$649,4,FALSE) -> 4 - Low | N11: =VLOOKUP(Requests[[#This Row],[Priority]],'SLA Config'!$B$3:$C$6,2,FALSE) -> 25 | O11: =IF(Requests[[#This Row],[Age (days)]]>Requests[[#This Row],[SLA Threshold]],"Yes","No") -> No
A12: RF3892781 | B12: 44806 | C12: 44818 | D12: Closed | E12: SIRIVV02 | F12: =IF(ISBLANK(C12), NETWORKDAYS(B12,TODAY()), NETWORKDAYS(B12,C12)) -> 9 | G12: CHAMP | H12: CHAMP Access updates | I12: User Access | J12: Update permissions | K12: TROUGHT, ALLISON | L12: Business | M12: =VLOOKUP(Requests[[#This Row],[Ticket ID]],[2]Requests!$A$2:$D$649,4,FALSE) -> 4 - Low | N12: =VLOOKUP(Requests[[#This Row],[Priority]],'SLA Config'!$B$3:$C$6,2,FALSE) -> 25 | O12: =IF(Requests[[#This Row],[Age (days)]]>Requests[[#This Row],[SLA Threshold]],"Yes","No") -> No
A13: RF3893669 | B13: 44806 | C13: 44818 | D13: Closed | E13: SIRIVV02 | F13: =IF(ISBLANK(C13), NETWORKDAYS(B13,TODAY()), NETWORKDAYS(B13,C13)) -> 9 | G13: CHAMP | H13: Patient Insights - Remove Access | I13: User Access | J13: Remove | K13: TROUGHT, ALLISON | L13: Business | M13: =VLOOKUP(Requests[[#This Row],[Ticket ID]],[2]Requests!$A$2:$D$649,4,FALSE) -> 4 - Low | N13: =VLOOKUP(Requests[[#This Row],[Priority]],'SLA Config'!$B$3:$C$6,2,FALSE) -> 25 | O13: =IF(Requests[[#This Row],[Age (days)]]>Requests[[#This Row],[SLA Threshold]],"Yes","No") -> No
... A361: RF5111071 | B361: 45518 | C361: 45525 | D361: Closed | E361: BABUS32 | F361: =IF(ISBLANK(C361), NETWORKDAYS(B361,TODAY()), NETWORKDAYS(B361,C361)) -> 6 | G361: PASSPORT | H361: RM Fulfillment Ticket: Patient Insights - 20240813170036309 | I361: User Access | J361: Add | K361: HOFFNER, COREY | L361: Business | M361: =VLOOKUP(Requests[[#This Row],[Ticket ID]],[2]Requests!$A$2:$D$649,4,FALSE) -> 4 - Low | N361: =VLOOKUP(Requests[[#This Row],[Priority]],'SLA Config'!$B$3:$C$6,2,FALSE) -> 25 | O361: =IF(Requests[[#This Row],[Age (days)]]>Requests[[#This Row],[SLA Threshold]],"Yes","No") -> No
A362: RF5439801 | B362: 45722 | C362: 45747 | D362: Closed | E362: GUNDAP04 | F362: =IF(ISBLANK(C362), NETWORKDAYS(B362,TODAY()), NETWORKDAYS(B362,C362)) -> 18 | G362: PASSPORT | H362: PATIENTINSIGHTS-PROD-P&ALEGAL - New dashboard request | K362: WANG, ERIC | L362: Business | M362: =VLOOKUP(Requests[[#This Row],[Ticket ID]],[2]Requests!$A$2:$D$649,4,FALSE) -> 4 - Low | N362: =VLOOKUP(Requests[[#This Row],[Priority]],'SLA Config'!$B$3:$C$6,2,FALSE) -> 25 | O362: =IF(Requests[[#This Row],[Age (days)]]>Requests[[#This Row],[SLA Threshold]],"Yes","No") -> No
A363: RF5112494 | B363: 45518 | C363: 45542 | D363: Closed | E363: DINALK01 | F363: =IF(ISBLANK(C363), NETWORKDAYS(B363,TODAY()), NETWORKDAYS(B363,C363)) -> 18 | G363: PASSPORT | H363: Patient Insights - Enhancement Request - Patient Journey TAT update | I363: Enhancement | J363: Tableau | K363: WANG, ERIC | L363: Business | M363: =VLOOKUP(Requests[[#This Row],[Ticket ID]],[2]Requests!$A$2:$D$649,4,FALSE) -> 4 - Low | N363: =VLOOKUP(Requests[[#This Row],[Priority]],'SLA Config'!$B$3:$C$6,2,FALSE) -> 25 | O363: =IF(Requests[[#This Row],[Age (days)]]>Requests[[#This Row],[SLA Threshold]],"Yes","No") -> No
A364: RF5114035 | B364: 45519 | C364: 45542 | D364: Closed | E364: GUNDAP04 | F364: =IF(ISBLANK(C364), NETWORKDAYS(B364,TODAY()), NETWORKDAYS(B364,C364)) -> 17 | G364: CHAMP | H364: Patient Insights - Add new services in CHAMP/Patient Point | I364: Enhancement | J364: Data Update | K364: TROUGHT, ALLISON | L364: Business | M364: =VLOOKUP(Requests[[#This Row],[Ticket ID]],[2]Requests!$A$2:$D$649,4,FALSE) -> 4 - Low | N364: =VLOOKUP(Requests[[#This Row],[Priority]],'SLA Config'!$B$3:$C$6,2,FALSE) -> 25 | O364: =IF(Requests[[#This Row],[Age (days)]]>Requests[[#This Row],[SLA Threshold]],"Yes","No") -> No
A365: RF5114692 | B365: 45520 | C365: 45537 | D365: Closed | E365: DINALK01 | F365: =IF(ISBLANK(C365), NETWORKDAYS(B365,TODAY()), NETWORKDAYS(B365,C365)) -> 12 | G365: PASSPORT | H365: Patient Insights | Patient Experience & Hub Scorecard questions | I365: Report | J365: Question | K365: WANG, ERIC | L365: Business | M365: =VLOOKUP(Requests[[#This Row],[Ticket ID]],[2]Requests!$A$2:$D$649,4,FALSE) -> 4 - Low | N365: =VLOOKUP(Requests[[#This Row],[Priority]],'SLA Config'!$B$3:$C$6,2,FALSE) -> 25 | O365: =IF(Requests[[#This Row],[Age (days)]]>Requests[[#This Row],[SLA Threshold]],"Yes","No") -> No
A366: RF5116312 | B366: 45523 | C366: 45529 | D366: Closed | E366: MALLIA04 | F366: =IF(ISBLANK(C366), NETWORKDAYS(B366,TODAY()), NETWORKDAYS(B366,C366)) -> 5 | G366: PASSPORT | H366: Patient Insights | Authorized for therapy update date - to ingest latest data for Velsipity brand activity | I366: Enhancement | J366: Data Update | K366: DINALIS, KONSTANTINOS | L366: Support | M366: =VLOOKUP(Requests[[#This Row],[Ticket ID]],[2]Requests!$A$2:$D$649,4,FALSE) -> 4 - Low | N366: =VLOOKUP(Requests[[#This Row],[Priority]],'SLA Config'!$B$3:$C$6,2,FALSE) -> 25 | O366: =IF(Requests[[#This Row],[Age (days)]]>Requests[[#This Row],[SLA Threshold]],"Yes","No") -> No
A367: RF5124006 | B367: 45526 | C367: 45535 | D367: Closed | E367: MALLIA04 | F367: =IF(ISBLANK(C367), NETWORKDAYS(B367,TODAY()), NETWORKDAYS(B367,C367)) -> 7 | G367: CHAMP | H367: Patient Insights | Insert data into XREF table - SPP v 867 | I367: Enhancement | J367: Data Update | K367: ANANTHAKRISHNAN, MAHADEVAN | L367: Digital | M367: =VLOOKUP(Requests[[#This Row],[Ticket ID]],[2]Requests!$A$2:$D$649,4,FALSE) -> 3 - Medium | N367: =VLOOKUP(Requests[[#This Row],[Priority]],'SLA Config'!$B$3:$C$6,2,FALSE) -> 15 | O367: =IF(Requests[[#This Row],[Age (days)]]>Requests[[#This Row],[SLA Threshold]],"Yes","No") -> No
A368: RF5132117 | B368: 45531 | C368: 45558 | D368: Closed | E368: DINALK01 | F368: =IF(ISBLANK(C368), NETWORKDAYS(B368,TODAY()), NETWORKDAYS(B368,C368)) -> 20 | G368: PASSPORT | H368: PI Hub Scorecard - Vyndalink Interim Care case/subcase type mapping | I368: Enhancement | J368: Tableau | K368: WANG, ERIC | L368: Business | M368: =VLOOKUP(Requests[[#This Row],[Ticket ID]],[2]Requests!$A$2:$D$649,4,FALSE) -> 4 - Low | N368: =VLOOKUP(Requests[[#This Row],[Priority]],'SLA Config'!$B$3:$C$6,2,FALSE) -> 25 | O368: =IF(Requests[[#This Row],[Age (days)]]>Requests[[#This Row],[SLA Threshold]],"Yes","No") -> No
A369: RF5133885 | B369: 45532 | C369: 45532 | D369: Closed | E369: MALLIA04 | F369: =IF(ISBLANK(C369), NETWORKDAYS(B369,TODAY()), NETWORKDAYS(B369,C369)) -> 1 | G369: PASSPORT | H369: Patient Insights - Hub Scorecard - Interim Care Program mapping | I369: Enhancement | J369: Tableau | K369: WANG, ERIC | L369: Business | M369: =VLOOKUP(Requests[[#This Row],[Ticket ID]],[2]Requests!$A$2:$D$649,4,FALSE) -> 4 - Low | N369: =VLOOKUP(Requests[[#This Row],[Priority]],'SLA Config'!$B$3:$C$6,2,FALSE) -> 25 | O369: =IF(Requests[[#This Row],[Age (days)]]>Requests[[#This Row],[SLA Threshold]],"Yes","No") -> No
A370: RF5134821 | B370: 45532 | C370: 45543 | D370: Closed | E370: BABUS32 | F370: =IF(ISBLANK(C370), NETWORKDAYS(B370,TODAY()), NETWORKDAYS(B370,C370)) -> 8 | G370: CHAMP | H370: Patient Point - Notification question when updating contract or services | I370: Report | J370: Question | K370: TROUGHT, ALLISON | L370: Business | M370: =VLOOKUP(Requests[[#This Row],[Ticket ID]],[2]Requests!$A$2:$D$649,4,FALSE) -> 4 - Low | N370: =VLOOKUP(Requests[[#This Row],[Priority]],'SLA Config'!$B$3:$C$6,2,FALSE) -> 25 | O370: =IF(Requests[[#This Row],[Age (days)]]>Requests[[#This Row],[SLA Threshold]],"Yes","No") -> No
A371: RF5136257 | B371: 45533 | C371: 45553 | D371: Closed | E371: GUNDAP04 | F371: =IF(ISBLANK(C371), NETWORKDAYS(B371,TODAY()), NETWORKDAYS(B371,C371)) -> 15 | G371: CHAMP | H371: Patient Insights - Add new SPP | I371: Enhancement | J371: Data Update | K371: TROUGHT, ALLISON | L371: Business | M371: =VLOOKUP(Requests[[#This Row],[Ticket ID]],[2]Requests!$A$2:$D$649,4,FALSE) -> 4 - Low | N371: =VLOOKUP(Requests[[#This Row],[Priority]],'SLA Config'!$B$3:$C$6,2,FALSE) -> 25 | O371: =IF(Requests[[#This Row],[Age (days)]]>Requests[[#This Row],[SLA Threshold]],"Yes","No") -> No
A372: RF5139954 | B372: 45537 | C372: 45578 | D372: Closed | E372: GUNDAP04 | F372: =IF(ISBLANK(C372), NETWORKDAYS(B372,TODAY()), NETWORKDAYS(B372,C372)) -> 30 | G372: PASSPORT | H372: RM Fulfillment Ticket: Patient Insights - 20240827224946838 | I372: User Access | J372: Add | K372: DILOLLO, STEVEN BERTRAND | L372: Business | M372: =VLOOKUP(Requests[[#This Row],[Ticket ID]],[2]Requests!$A$2:$D$649,4,FALSE) -> 4 - Low | N372: =VLOOKUP(Requests[[#This Row],[Priority]],'SLA Config'!$B$3:$C$6,2,FALSE) -> 25 | O372: =IF(Requests[[#This Row],[Age (days)]]>Requests[[#This Row],[SLA Threshold]],"Yes","No") -> Yes
A373: RF5139955 | B373: 45537 | C373: 45577 | D373: Closed | E373: GUNDAP04 | F373: =IF(ISBLANK(C373), NETWORKDAYS(B373,TODAY()), NETWORKDAYS(B373,C373)) -> 30 | G373: PASSPORT | H373: RM Fulfillment Ticket: Patient Insights - 20240827224811836 | I373: User Access | J373: Add | K373: WATKINS, NATALIE MARY | L373: Business | M373: =VLOOKUP(Requests[[#This Row],[Ticket ID]],[2]Requests!$A$2:$D$649,4,FALSE) -> 4 - Low | N373: =VLOOKUP(Requests[[#This Row],[Priority]],'SLA Config'!$B$3:$C$6,2,FALSE) -> 25 | O373: =IF(Requests[[#This Row],[Age (days)]]>Requests[[#This Row],[SLA Threshold]],"Yes","No") -> Yes
A374: RF5139956 | B374: 45537 | C374: 45578 | D374: Closed | E374: GUNDAP04 | F374: =IF(ISBLANK(C374), NETWORKDAYS(B374,TODAY()), NETWORKDAYS(B374,C374)) -> 30 | G374: PASSPORT | H374: RM Fulfillment Ticket: Patient Insights - 20240827224328833 | I374: User Access | J374: Add | K374: BROADUS, ALEXANDRA LAMBERT | L374: Business | M374: =VLOOKUP(Requests[[#This Row],[Ticket ID]],[2]Requests!$A$2:$D$649,4,FALSE) -> 4 - Low | N374: =VLOOKUP(Requests[[#This Row],[Priority]],'SLA Config'!$B$3:$C$6,2,FALSE) -> 25 | O374: =IF(Requests[[#This Row],[Age (days)]]>Requests[[#This Row],[SLA Threshold]],"Yes","No") -> Yes
... A424: RF5256886 | B424: 45604 | C424: 45622 | D424: Closed | E424: BABUS32 | F424: =IF(ISBLANK(C424), NETWORKDAYS(B424,TODAY()), NETWORKDAYS(B424,C424)) -> 13 | G424: PASSPORT | H424: RM Fulfillment Ticket: Patient Insights - 20241107154250767 | I424: User Access | J424: Add | K424: HULL, MICHAEL ROBERT | L424: Business | M424: =VLOOKUP(Requests[[#This Row],[Ticket ID]],[2]Requests!$A$2:$D$649,4,FALSE) -> 4 - Low | N424: =VLOOKUP(Requests[[#This Row],[Priority]],'SLA Config'!$B$3:$C$6,2,FALSE) -> 25 | O424: =IF(Requests[[#This Row],[Age (days)]]>Requests[[#This Row],[SLA Threshold]],"Yes","No") -> No
A425: RF5257332 | B425: 45604 | C425: 45613 | D425: Closed | F425: =IF(ISBLANK(C425), NETWORKDAYS(B425,TODAY()), NETWORKDAYS(B425,C425)) -> 6 | G425: PASSPORT | H425: Patient Insights | Vyndamax Target List Manual Upload to Stage and Dev | I425: Enhancement | J425: Data Update | K425: PARAMESWARAN, KARTHIGA | L425: Digital | M425: =VLOOKUP(Requests[[#This Row],[Ticket ID]],[2]Requests!$A$2:$D$649,4,FALSE) -> 4 - Low | N425: =VLOOKUP(Requests[[#This Row],[Priority]],'SLA Config'!$B$3:$C$6,2,FALSE) -> 25 | O425: =IF(Requests[[#This Row],[Age (days)]]>Requests[[#This Row],[SLA Threshold]],"Yes","No") -> No
A426: RF5259075 | B426: 45605 | C426: 45612 | D426: Closed | E426: DINALK01 | F426: =IF(ISBLANK(C426), NETWORKDAYS(B426,TODAY()), NETWORKDAYS(B426,C426)) -> 5 | G426: CONFIGURATION MANAGEMENT | H426: SM Data Quality Discrepancy Report [Change Mgmt General]: GBL-C4 MARM PATIENT INSIGHTS SUPPORT | K426: DIGITAL CONFIGURATION MGMT, CI DATA QUALITY | L426: Digital | M426: =VLOOKUP(Requests[[#This Row],[Ticket ID]],[2]Requests!$A$2:$D$649,4,FALSE) -> 4 - Low | N426: =VLOOKUP(Requests[[#This Row],[Priority]],'SLA Config'!$B$3:$C$6,2,FALSE) -> 25 | O426: =IF(Requests[[#This Row],[Age (days)]]>Requests[[#This Row],[SLA Threshold]],"Yes","No") -> No
A427: RF5260440 | B427: 45607 | C427: 45620 | D427: Closed | E427: BABUS32 | F427: =IF(ISBLANK(C427), NETWORKDAYS(B427,TODAY()), NETWORKDAYS(B427,C427)) -> 10 | G427: PASSPORT | H427: RM Fulfillment Ticket: Patient Insights - 20241111025632846 | K427: DINALIS, KONSTANTINOS | L427: Digital | M427: =VLOOKUP(Requests[[#This Row],[Ticket ID]],[2]Requests!$A$2:$D$649,4,FALSE) -> 4 - Low | N427: =VLOOKUP(Requests[[#This Row],[Priority]],'SLA Config'!$B$3:$C$6,2,FALSE) -> 25 | O427: =IF(Requests[[#This Row],[Age (days)]]>Requests[[#This Row],[SLA Threshold]],"Yes","No") -> No
A428: RF5260442 | B428: 45607 | C428: 45620 | D428: Closed | E428: BABUS32 | F428: =IF(ISBLANK(C428), NETWORKDAYS(B428,TODAY()), NETWORKDAYS(B428,C428)) -> 10 | G428: PASSPORT | H428: RM Fulfillment Ticket: Patient Insights - 20241111025539841 | K428: DINALIS, KONSTANTINOS | L428: Digital | M428: =VLOOKUP(Requests[[#This Row],[Ticket ID]],[2]Requests!$A$2:$D$649,4,FALSE) -> 4 - Low | N428: =VLOOKUP(Requests[[#This Row],[Priority]],'SLA Config'!$B$3:$C$6,2,FALSE) -> 25 | O428: =IF(Requests[[#This Row],[Age (days)]]>Requests[[#This Row],[SLA Threshold]],"Yes","No") -> No
A429: RF5260443 | B429: 45607 | C429: 45623 | D429: Closed | E429: BABUS32 | F429: =IF(ISBLANK(C429), NETWORKDAYS(B429,TODAY()), NETWORKDAYS(B429,C429)) -> 13 | G429: PASSPORT | H429: RM Fulfillment Ticket: Patient Insights - 20241111025720850 | K429: DINALIS, KONSTANTINOS | L429: Digital | M429: =VLOOKUP(Requests[[#This Row],[Ticket ID]],[2]Requests!$A$2:$D$649,4,FALSE) -> 4 - Low | N429: =VLOOKUP(Requests[[#This Row],[Priority]],'SLA Config'!$B$3:$C$6,2,FALSE) -> 25 | O429: =IF(Requests[[#This Row],[Age (days)]]>Requests[[#This Row],[SLA Threshold]],"Yes","No") -> No
A430: RF5260254 | B430: 45607 | C430: 45628 | D430: Closed | E430: BABUS32 | F430: =IF(ISBLANK(C430), NETWORKDAYS(B430,TODAY()), NETWORKDAYS(B430,C430)) -> 16 | G430: PASSPORT | H430: RM Fulfillment Ticket: Patient Insights - 20241111025950857 | K430: DINALIS, KONSTANTINOS | L430: Digital | M430: =VLOOKUP(Requests[[#This Row],[Ticket ID]],[2]Requests!$A$2:$D$649,4,FALSE) -> 4 - Low | N430: =VLOOKUP(Requests[[#This Row],[Priority]],'SLA Config'!$B$3:$C$6,2,FALSE) -> 25 | O430: =IF(Requests[[#This Row],[Age (days)]]>Requests[[#This Row],[SLA Threshold]],"Yes","No") -> No
A431: RF5261823 | B431: 45608 | C431: 45664 | D431: Closed | E431: GUNDAP04 | F431: =IF(ISBLANK(C431), NETWORKDAYS(B431,TODAY()), NETWORKDAYS(B431,C431)) -> 41 | G431: PASSPORT | H431: Patient Insights | Create new group "MASPA DTR" | K431: WANG, ERIC | L431: Business | M431: =VLOOKUP(Requests[[#This Row],[Ticket ID]],[2]Requests!$A$2:$D$649,4,FALSE) -> 4 - Low | N431: =VLOOKUP(Requests[[#This Row],[Priority]],'SLA Config'!$B$3:$C$6,2,FALSE) -> 25 | O431: =IF(Requests[[#This Row],[Age (days)]]>Requests[[#This Row],[SLA Threshold]],"Yes","No") -> Yes
A432: RF5266697 | B432: 45610 | C432: 45615 | D432: Closed | E432: BABUS32 | F432: =IF(ISBLANK(C432), NETWORKDAYS(B432,TODAY()), NETWORKDAYS(B432,C432)) -> 4 | G432: PASSPORT | H432: Patient Insights | Vyndamax Target List Manual Table Creation | K432: PATRO, P SAURAV KUMAR | L432: Digital | M432: =VLOOKUP(Requests[[#This Row],[Ticket ID]],[2]Requests!$A$2:$D$649,4,FALSE) -> 4 - Low | N432: =VLOOKUP(Requests[[#This Row],[Priority]],'SLA Config'!$B$3:$C$6,2,FALSE) -> 25 | O432: =IF(Requests[[#This Row],[Age (days)]]>Requests[[#This Row],[SLA Threshold]],"Yes","No") -> No
A433: RF5270185 | B433: 45611 | C433: 45634 | D433: Closed | E433: GUNDAP04 | F433: =IF(ISBLANK(C433), NETWORKDAYS(B433,TODAY()), NETWORKDAYS(B433,C433)) -> 16 | G433: PASSPORT | H433: Patient Insights - User activity statistics | K433: KARDI, PANDE PUTU ADYSTI | L433: Digital | M433: =VLOOKUP(Requests[[#This Row],[Ticket ID]],[2]Requests!$A$2:$D$649,4,FALSE) -> 4 - Low | N433: =VLOOKUP(Requests[[#This Row],[Priority]],'SLA Config'!$B$3:$C$6,2,FALSE) -> 25 | O433: =IF(Requests[[#This Row],[Age (days)]]>Requests[[#This Row],[SLA Threshold]],"Yes","No") -> No
A434: RF5272763 | B434: 45614 | C434: 45633 | D434: Closed | E434: GUNDAP04 | F434: =IF(ISBLANK(C434), NETWORKDAYS(B434,TODAY()), NETWORKDAYS(B434,C434)) -> 15 | G434: PASSPORT | H434: Patient Insights - Number of dashboard views | K434: KARDI, PANDE PUTU ADYSTI | L434: Digital | M434: =VLOOKUP(Requests[[#This Row],[Ticket ID]],[2]Requests!$A$2:$D$649,4,FALSE) -> 4 - Low | N434: =VLOOKUP(Requests[[#This Row],[Priority]],'SLA Config'!$B$3:$C$6,2,FALSE) -> 25 | O434: =IF(Requests[[#This Row],[Age (days)]]>Requests[[#This Row],[SLA Threshold]],"Yes","No") -> No
A435: RF5260253 | B435: 45607 | C435: 45620 | D435: Closed | E435: BABUS32 | F435: =IF(ISBLANK(C435), NETWORKDAYS(B435,TODAY()), NETWORKDAYS(B435,C435)) -> 10 | G435: PASSPORT | H435: RM Fulfillment Ticket: Patient Insights - 20241111030044858 | K435: DINALIS, KONSTANTINOS | L435: Support | M435: =VLOOKUP(Requests[[#This Row],[Ticket ID]],[2]Requests!$A$2:$D$649,4,FALSE) -> 4 - Low | N435: =VLOOKUP(Requests[[#This Row],[Priority]],'SLA Config'!$B$3:$C$6,2,FALSE) -> 25 | O435: =IF(Requests[[#This Row],[Age (days)]]>Requests[[#This Row],[SLA Threshold]],"Yes","No") -> No
A436: RF5278190 | B436: 45617 | C436: 45627 | D436: Closed | E436: DINALK01 | F436: =IF(ISBLANK(C436), NETWORKDAYS(B436,TODAY()), NETWORKDAYS(B436,C436)) -> 7 | G436: PASSPORT | H436: Patient Insights | AMBA data extract | K436: GOLDSMITH, GEORGE | L436: Business | M436: =VLOOKUP(Requests[[#This Row],[Ticket ID]],[2]Requests!$A$2:$D$649,4,FALSE) -> 3 - Medium | N436: =VLOOKUP(Requests[[#This Row],[Priority]],'SLA Config'!$B$3:$C$6,2,FALSE) -> 15 | O436: =IF(Requests[[#This Row],[Age (days)]]>Requests[[#This Row],[SLA Threshold]],"Yes","No") -> No
...

Sheet Problems
A1: Ticket ID | B1: Opened On | C1: Closed On | D1: Phase | E1: Assignee | F1: Age (days) | G1: Description | H1: Related Tickets | I1: Category | J1: Subcategory | K1: Requested By
A2: PM7003565 | B2: 44799 | C2: 44813 | D2: Closed | E2: SIRIVV02 | F2: =IF(ISBLANK(C2), TODAY() - B2, C2-B2) -> 14 | G2: Derm files -- we are receiving files with unexpected file name format . Opening this problem to track the issue. | I2: Interface Issue | J2: Interface Failure | K2: Support
A3: PM7003631 | B3: 44818 | C3: 44844 | D3: Closed | E3: SIRIVV02 | F3: =IF(ISBLANK(C3), TODAY() - B3, C3-B3) -> 26 | G3: DERM Job is getting failed daily(from 8-sep-2022) with the error "Invalid header in one of the derm files" | I3: Interface Issue | J3: Interface Failure | K3: Support
A4: PM7003681 | B4: 44830 | C4: 44834 | D4: Closed | E4: SIRIVV02 | F4: =IF(ISBLANK(C4), TODAY() - B4, C4-B4) -> 4 | G4: POT Files || We are receiving wrong files daily. Receiving files with mismatch dates in control file vs data files. This issue is recurring form 16th september. | I4: Interface Issue | J4: Interface Failure | K4: Support
A5: PM7003731 | B5: 44840 | C5: 44858 | D5: Closed | E5: SIRIVV02 | F5: =IF(ISBLANK(C5), TODAY() - B5, C5-B5) -> 18 | G5: POT files are diverted to Dev sever with an extra file 18+1 Hence IICS POT job in prod is failing | I5: Interface Issue | J5: Interface Failure | K5: Support
A6: PM7003914 | B6: 44887 | C6: 44908 | D6: Closed | E6: SIRIVV02 | F6: =IF(ISBLANK(C6), TODAY() - B6, C6-B6) -> 21 | G6: We are not receiving POT files before the scheduled time of IICS job | I6: Interface Issue | J6: Interface Failure | K6: Support
A7: PM7004937 | B7: 45076 | D7: Work in progress | E7: MALLIA04 | F7: =IF(ISBLANK(C7), TODAY() - B7, C7-B7) -> 1039 | G7: Champ master task flow is executing completely even when there are failures in subtasks, which is leading to load partial data/no data in dashboard | I7: Batch | J7: Interface Failure | K7: Support
A8: PM7004984 | B8: 45083 | C8: 45146 | D8: Closed | E8: MALLIA04 | F8: =IF(ISBLANK(C8), TODAY() - B8, C8-B8) -> 63 | G8: Patient insights support DL was not included in any of the incremental file load related jobs like DERM, POT & Bridge , These jobs feeds the data for Patient experience reports | I8: Batch | J8: IICS | K8: Support
A9: PM7005156 | B9: 45119 | C9: 45126 | D9: Closed | E9: SIRIVV02 | F9: =IF(ISBLANK(C9), TODAY() - B9, C9-B9) -> 7 | G9: DERM Job is getting failed from 7/4 as we are receiving new additional file called authorization file. | I9: Batch | J9: IICS | K9: Support
A10: PM7005215 | B10: 45128 | C10: 45146 | D10: Closed | E10: MALLIA04 | F10: =IF(ISBLANK(C10), TODAY() - B10, C10-B10) -> 18 | G10: Patient master taskflow is getting failed in production server after IICS R43 upgrade, Due to which the master patient job is getting failed and we need to trigger the job manually every time | I10: Batch | J10: IICS | K10: Support
A11: PM7005266 | B11: 45141 | C11: 45180 | D11: Closed | E11: DINALK01 | F11: =IF(ISBLANK(C11), TODAY() - B11, C11-B11) -> 39 | G11: Patient Insights | Fix non-conforming service accounts | I11: Audit | J11: Service Accounts | K11: Support
A12: PM7005291 | B12: 45146 | D12: Work in progress | E12: MALLIA04 | F12: =IF(ISBLANK(C12), TODAY() - B12, C12-B12) -> 969 | G12: Patient insights support DL was not included in any of the incremental file load related jobs like DERM, POT & Bridge , These jobs feeds the data for Patient experience reports | H12: PM7004984 | I12: Batch | J12: IICS | K12: Support
A13: PM7005349 | B13: 45160 | C13: 45313 | D13: Closed | E13: MALLIA04 | F13: =IF(ISBLANK(C13), TODAY() - B13, C13-B13) -> 153 | G13: Revoke Write access for Digital Patient Insights team from UAT environment | I13: User Access | J13: IICS | K13: Support
A14: PM7005524 | B14: 45191 | C14: 45232 | D14: Closed | E14: MALLIA04 | F14: =IF(ISBLANK(C14), TODAY() - B14, C14-B14) -> 41 | G14: Patient Insights | Copy control files from GBT HUB folder to GBT SPIF folder | I14: Interface Issue | J14: Interface Failure | K14: Support
A15: PM7005539 | B15: 45195 | C15: 45412 | D15: Closed | E15: DINALK01 | F15: =IF(ISBLANK(C15), TODAY() - B15, C15-B15) -> 217 | G15: Patient Insights | LASH | Multiple Patient ID tagged to 1 Case ID | I15: Data Issue | J15: LASH | K15: Support
A16: PM7005551 | B16: 45196 | C16: 45219 | D16: Closed | E16: ANANDA40 | F16: =IF(ISBLANK(C16), TODAY() - B16, C16-B16) -> 23 | G16: Patient Insights | GBT HUB | Control file name incorrect | I16: Interface Issue | J16: Interface Failure | K16: Support
A17: PM7005858 | B17: 45251 | C17: 45330 | D17: Closed | E17: BABUS32 | F17: =IF(ISBLANK(C17), TODAY() - B17, C17-B17) -> 79 | G17: Patient Insights | GitHub Dependabot alerts | I17: Environment | J17: GitHub | K17: Support
A18: PM7005892 | B18: 45258 | C18: 45279 | D18: Closed | E18: ANANDA40 | F18: =IF(ISBLANK(C18), TODAY() - B18, C18-B18) -> 21 | G18: Patient Insights | GBT HUB | Incorrect Control File | I18: Batch | J18: Interface Failure | K18: Support
A19: PM7006137 | B19: 45314 | C19: 45321 | D19: Closed | E19: GANJIR04 | F19: =IF(ISBLANK(C19), TODAY() - B19, C19-B19) -> 7 | G19: Patient Insights - CHAMP does not display the 2024 data | I19: Data Issue | J19: Tableau | K19: Support
A20: PM7006205 | B20: 45327 | D20: Work in progress | E20: ANANDA40 | F20: =IF(ISBLANK(C20), TODAY() - B20, C20-B20) -> 788 | G20: Patient Insights | Permanently fix IICS script failure for Tableau refresh | I20: Batch | J20: IICS | K20: Support
A21: PM7006215 | B21: 45329 | C21: 45369 | D21: Closed | E21: ANANDA40 | F21: =IF(ISBLANK(C21), TODAY() - B21, C21-B21) -> 40 | G21: Patient Insights | Fix Datasource Refresh Automatic Schdeule | I21: Batch | J21: IICS | K21: Support
A22: PM7006420 | B22: 45370 | D22: Work in progress | E22: MALLIA04 | F22: =IF(ISBLANK(C22), TODAY() - B22, C22-B22) -> 745 | G22: Biohaven IC Report data ingestion issue | S3 path inconsistency | I22: Batch | J22: IICS | K22: Support
A23: PM7006549 | B23: 45401 | C23: 45427 | D23: Closed | E23: MALLIA04 | F23: =IF(ISBLANK(C23), TODAY() - B23, C23-B23) -> 26 | G23: Patient Insights | Patient Experience data extract refresh and ETL job misalignment | I23: Batch | J23: IICS | K23: Support
A24: PM7006652 | B24: 45428 | C24: 45463 | D24: Closed | E24: ANANDA40 | F24: =IF(ISBLANK(C24), TODAY() - B24, C24-B24) -> 35 | G24: Patient Insight | 2 email for Job- Failure on Production | I24: Batch | J24: IICS | K24: Support
A25: PM7006689 | B25: 45434 | C25: 45527 | D25: Closed | E25: MALLIA04 | F25: =IF(ISBLANK(C25), TODAY() - B25, C25-B25) -> 93 | G25: Patient Insight: Automation of Job failures and Recommendation through Gen AI | I25: Batch | J25: IICS | K25: Support
A26: PM7006690 | B26: 45434 | C26: 45518 | D26: Closed | E26: MALLIA04 | F26: =IF(ISBLANK(C26), TODAY() - B26, C26-B26) -> 84 | G26: Patient Insight: Auto ticket assignment for Patient Insight Application | I26: Environment | J26: Service Manager | K26: Support
A27: PM7006691 | B27: 45434 | C27: 45477 | D27: Closed | E27: MALLIA04 | F27: =IF(ISBLANK(C27), TODAY() - B27, C27-B27) -> 43 | G27: Patient Insight: PAM alert | I27: Environment | J27: Monitoring | K27: Support
A28: PM7006728 | B28: 45441 | C28: 45446 | D28: Closed | E28: ANANDA40 | F28: =IF(ISBLANK(C28), TODAY() - B28, C28-B28) -> 5 | G28: Patient Insight | BHVN HCP Interface Failure | I28: Interface Issue | J28: Interface Failure | K28: Support
A29: PM7006922 | B29: 45476 | C29: 45490 | D29: Closed | E29: ANANDA40 | F29: =IF(ISBLANK(C29), TODAY() - B29, C29-B29) -> 14 | G29: Patient Insights | Set up notification process for GMFT jobs | I29: Environment | J29: Monitoring | K29: Support
A30: PM7006970 | B30: 45490 | D30: Work in progress | E30: BABUS32 | F30: =IF(ISBLANK(C30), TODAY() - B30, C30-B30) -> 625 | G30: Patient Insights | Dashboard access validation and streamline user access request | I30: User Access | J30: Report | K30: Support
A31: PM7007085 | B31: 45520 | C31: 45609 | D31: Closed | E31: BABUS32 | F31: =IF(ISBLANK(C31), TODAY() - B31, C31-B31) -> 89 | G31: Patient Insight | Fix GitHub vulnerabilities | I31: Environment | J31: Web App | K31: Support
A32: PM7007167 | B32: 45530 | D32: Work in progress | E32: MALLIA04 | F32: =IF(ISBLANK(C32), TODAY() - B32, C32-B32) -> 585 | G32: Patient Insights | Milliman Payer file notification missing | I32: Batch | J32: IICS | K32: Support
A33: PM7007244 | B33: 45545 | D33: Closed | E33: MALLIA04 | F33: =IF(ISBLANK(C33), TODAY() - B33, C33-B33) -> 570 | G33: Patient Insights | SPP V867 data issue | I33: Data Issue | J33: Tableau | K33: Support
A34: PM7007570 | B34: 45625 | C34: 45728 | D34: Closed | E34: ANANDA40 | F34: =IF(ISBLANK(C34), TODAY() - B34, C34-B34) -> 103 | G34: Patient Insights | Schedule Tableau Refresh | K34: Support
A35: PM7007724 | B35: 45664 | D35: Work in Progress | E35: ANANDA40 | F35: =IF(ISBLANK(C35), TODAY() - B35, C35-B35) -> 451 | G35: Patient Insights | TF_ES_Financial_load & TF_ES_Impact_Load - Data mismatch in specific columns | K35: Support
A36: PM7007836 | B36: 45694 | C36: 45728 | D36: Closed | E36: ANANDA40 | F36: =IF(ISBLANK(C36), TODAY() - B36, C36-B36) -> 34 | G36: Patient Insights | Remove GBT HUB from IICS monitoring | K36: Support
A37: PM7007899 | B37: 45713 | C37: 45728 | D37: Closed | E37: ANANDA40 | F37: =IF(ISBLANK(C37), TODAY() - B37, C37-B37) -> 15 | G37: Patient Insights | Job Failure in Production Envrionment (The root cause was escalated to the IICS Vendor and Network team, and the resolution involved stabilizing the job executions in production) | K37: Support
A38: PM7007952 | B38: 45721 | D38: Assign | E38: ANANDA40 | F38: =IF(ISBLANK(C38), TODAY() - B38, C38-B38) -> 394 | G38: Patient Insights | ES Intervention Mapping | K38: Support
A39: PM7007953 | B39: 45721 | D39: Assign | E39: ANANDA40 | F39: =IF(ISBLANK(C39), TODAY() - B39, C39-B39) -> 394 | G39: Patient Insights | ES Intervention Reason Mapping | K39: Support
A40: PM7007954 | B40: 45721 | D40: Work in Progress | E40: ANANDA40 | F40: =IF(ISBLANK(C40), TODAY() - B40, C40-B40) -> 394 | G40: Patient Insights | Velsipity I & I Load | K40: Support
...

Sheet (Hidden)
A1: Team | C1: Full Name | D1: Assignee
A2: All | C2: Kostas | D2: DINALK01
A3: Digital | C3: Anupama | D3: MALLIA04
A4: Business | C4: Vishnu | D4: SIRIVV02
A5: Project Team | C5: Ramesh | D5: GANJIR04
A6: Support | C6: Shridi | D6: BABUS32
C7: Ashish | D7: ANANDA40
C8: Punya | D8: GUNDAP04
C9: Uma | D9: CHANDU06
